<sdf version='1.6'>
  <world name='default'>
    <light name='sun' type='directional'>
      <cast_shadows>1</cast_shadows>
      <pose frame=''>0 0 10 0 -0 0</pose>
      <diffuse>0.8 0.8 0.8 1</diffuse>
      <specular>0.2 0.2 0.2 1</specular>
      <attenuation>
        <range>1000</range>
        <constant>0.9</constant>
        <linear>0.01</linear>
        <quadratic>0.001</quadratic>
      </attenuation>
      <direction>-0.5 0.1 -0.9</direction>
    </light>
    <model name='ground_plane'>
      <static>1</static>
      <link name='link'>
        <collision name='collision'>
          <geometry>
            <plane>
              <normal>0 0 1</normal>
              <size>100 100</size>
            </plane>
          </geometry>
          <surface>
            <contact>
              <collide_bitmask>65535</collide_bitmask>
              <ode/>
            </contact>
            <friction>
              <ode>
                <mu>100</mu>
                <mu2>50</mu2>
              </ode>
              <torsional>
                <ode/>
              </torsional>
            </friction>
            <bounce/>
          </surface>
          <max_contacts>10</max_contacts>
        </collision>
        <visual name='visual'>
          <cast_shadows>0</cast_shadows>
          <geometry>
            <plane>
              <normal>0 0 1</normal>
              <size>100 100</size>
            </plane>
          </geometry>
          <material>
            <script>
              <uri>file://media/materials/scripts/gazebo.material</uri>
              <name>Gazebo/Grey</name>
            </script>
          </material>
        </visual>
        <self_collide>0</self_collide>
        <enable_wind>0</enable_wind>
        <kinematic>0</kinematic>
      </link>
    </model>
    <gravity>0 0 -9.8</gravity>
    <magnetic_field>6e-06 2.3e-05 -4.2e-05</magnetic_field>
    <atmosphere type='adiabatic'/>
    <physics name='default_physics' default='0' type='ode'>
      <max_step_size>0.001</max_step_size>
      <real_time_factor>1</real_time_factor>
      <real_time_update_rate>1000</real_time_update_rate>
    </physics>
    <scene>
      <ambient>0.4 0.4 0.4 1</ambient>
      <background>0.7 0.7 0.7 1</background>
      <shadows>1</shadows>
    </scene>
    <audio>
      <device>default</device>
    </audio>
    <wind/>
    <spherical_coordinates>
      <surface_model>EARTH_WGS84</surface_model>
      <latitude_deg>0</latitude_deg>
      <longitude_deg>0</longitude_deg>
      <elevation>0</elevation>
      <heading_deg>0</heading_deg>
    </spherical_coordinates>
    <model name='robot'>
      <link name='mirbase_footprint'>
        <pose frame=''>0 0 0 0 -0 0</pose>
        <inertial>
          <pose frame=''>0.054604 1.7e-05 0.260633 0 -0 0</pose>
          <mass>72</mass>
          <inertia>
            <ixx>105.272</ixx>
            <ixy>-0.369106</ixy>
            <ixz>-0.695349</ixz>
            <iyy>108.339</iyy>
            <iyz>8.308e-05</iyz>
            <izz>107.786</izz>
          </inertia>
        </inertial>
        <collision name='mirbase_footprint_fixed_joint_lump__connecting_hardware_collision'>
          <pose frame=''>0.1 0 -0.1 1.57 -0 1.57</pose>
          <geometry>
            <mesh>
              <scale>0.001 0.001 0.001</scale>
              <uri>/home/larry/catkin_ws/src/sdl-packages/sdl_robot_description/meshes/working_copy_mm.stl</uri>
            </mesh>
          </geometry>
          <max_contacts>10</max_contacts>
          <surface>
            <contact>
              <ode/>
            </contact>
            <bounce/>
            <friction>
              <torsional>
                <ode/>
              </torsional>
              <ode/>
            </friction>
          </surface>
        </collision>
        <collision name='mirbase_footprint_fixed_joint_lump__camera_collision_1'>
          <pose frame=''>0.3 0 0.5 0 -0 0</pose>
          <geometry>
            <box>
              <size>0.073 0.276 0.072</size>
            </box>
          </geometry>
          <surface>
            <contact>
              <ode/>
            </contact>
            <friction>
              <ode/>
              <torsional>
                <ode/>
              </torsional>
            </friction>
            <bounce/>
          </surface>
          <max_contacts>10</max_contacts>
        </collision>
        <collision name='mirbase_footprint_fixed_joint_lump__base_link_collision_2'>
          <pose frame=''>0.325 0 0.85 0 -0 3.14159</pose>
          <geometry>
            <mesh>
              <scale>1 1 1</scale>
              <uri>/home/larry/catkin_ws/src/sdl-packages/sdl_robot_description/urdf/meshes/ur5e/collision/base.stl</uri>
            </mesh>
          </geometry>
          <max_contacts>10</max_contacts>
          <surface>
            <contact>
              <ode/>
            </contact>
            <bounce/>
            <friction>
              <torsional>
                <ode/>
              </torsional>
              <ode/>
            </friction>
          </surface>
        </collision>
        <collision name='mirbase_footprint_fixed_joint_lump__mirbase_link_collision_3'>
          <pose frame=''>0.037646 0 0 0 -0 0</pose>
          <geometry>
            <mesh>
              <scale>1 1 1</scale>
              <uri>/opt/ros/melodic/share/mir_description/meshes/collision/mir_100_base.stl</uri>
            </mesh>
          </geometry>
          <surface>
            <contact>
              <ode/>
            </contact>
            <friction>
              <ode/>
              <torsional>
                <ode/>
              </torsional>
            </friction>
            <bounce/>
          </surface>
          <max_contacts>10</max_contacts>
        </collision>
        <collision name='mirbase_footprint_fixed_joint_lump__mirback_laser_link_collision_4'>
          <pose frame=''>-0.3548 -0.2352 0.1914 -3.14159 -0 -2.35619</pose>
          <geometry>
            <mesh>
              <scale>1 1 1</scale>
              <uri>/opt/ros/melodic/share/mir_description/meshes/visual/sick_lms-100.stl</uri>
            </mesh>
          </geometry>
          <surface>
            <contact>
              <ode/>
            </contact>
            <friction>
              <ode/>
              <torsional>
                <ode/>
              </torsional>
            </friction>
            <bounce/>
          </surface>
          <max_contacts>10</max_contacts>
        </collision>
        <collision name='mirbase_footprint_fixed_joint_lump__mirfront_laser_link_collision_5'>
          <pose frame=''>0.4288 0.2358 0.1914 -3.14159 -0 0.785398</pose>
          <geometry>
            <mesh>
              <scale>1 1 1</scale>
              <uri>/opt/ros/melodic/share/mir_description/meshes/visual/sick_lms-100.stl</uri>
            </mesh>
          </geometry>
          <surface>
            <contact>
              <ode/>
            </contact>
            <friction>
              <ode/>
              <torsional>
                <ode/>
              </torsional>
            </friction>
            <bounce/>
          </surface>
          <max_contacts>10</max_contacts>
        </collision>
        <visual name='mirbase_footprint_fixed_joint_lump__connecting_hardware_visual'>
          <pose frame=''>0.1 0 -0.1 1.57 -0 1.57</pose>
          <geometry>
            <mesh>
              <scale>0.001 0.001 0.001</scale>
              <uri>/home/larry/catkin_ws/src/sdl-packages/sdl_robot_description/meshes/working_copy_mm.stl</uri>
            </mesh>
          </geometry>
        </visual>
        <visual name='mirbase_footprint_fixed_joint_lump__camera_visual_1'>
          <pose frame=''>0.3 0 0.5 0 -0 0</pose>
          <geometry>
            <mesh>
              <scale>1 1 1</scale>
              <uri>/home/larry/catkin_ws/src/sdl-packages/sdl_robot_description/urdf/meshes/kinect.dae</uri>
            </mesh>
          </geometry>
          <material>
            <script>
              <uri>__default__</uri>
              <name>__default__</name>
            </script>
          </material>
        </visual>
        <visual name='mirbase_footprint_fixed_joint_lump__base_link_visual_2'>
          <pose frame=''>0.325 0 0.85 0 -0 3.14159</pose>
          <geometry>
            <mesh>
              <scale>1 1 1</scale>
              <uri>/home/larry/catkin_ws/src/sdl-packages/sdl_robot_description/urdf/meshes/ur5e/visual/base.dae</uri>
            </mesh>
          </geometry>
        </visual>
        <visual name='mirbase_footprint_fixed_joint_lump__mirbase_link_visual_3'>
          <pose frame=''>0.037646 0 0 0 -0 0</pose>
          <geometry>
            <mesh>
              <scale>1 1 1</scale>
              <uri>/opt/ros/melodic/share/mir_description/meshes/visual/mir_100_base.stl</uri>
            </mesh>
          </geometry>
          <material>
            <script>
              <name>Gazebo/White</name>
              <uri>file://media/materials/scripts/gazebo.material</uri>
            </script>
          </material>
        </visual>
        <visual name='mirbase_footprint_fixed_joint_lump__mirback_laser_link_visual_4'>
          <pose frame=''>-0.3548 -0.2352 0.1914 -3.14159 -0 -2.35619</pose>
          <geometry>
            <mesh>
              <scale>1 1 1</scale>
              <uri>/opt/ros/melodic/share/mir_description/meshes/visual/sick_lms-100.stl</uri>
            </mesh>
          </geometry>
          <material>
            <script>
              <name>Gazebo/FlatBlack</name>
              <uri>file://media/materials/scripts/gazebo.material</uri>
            </script>
          </material>
        </visual>
        <visual name='mirbase_footprint_fixed_joint_lump__mirfront_laser_link_visual_5'>
          <pose frame=''>0.4288 0.2358 0.1914 -3.14159 -0 0.785398</pose>
          <geometry>
            <mesh>
              <scale>1 1 1</scale>
              <uri>/opt/ros/melodic/share/mir_description/meshes/visual/sick_lms-100.stl</uri>
            </mesh>
          </geometry>
          <material>
            <script>
              <name>Gazebo/FlatBlack</name>
              <uri>file://media/materials/scripts/gazebo.material</uri>
            </script>
          </material>
        </visual>
        <velocity_decay/>
        <sensor name='camera' type='depth'>
          <update_rate>20</update_rate>
          <camera name='__default__'>
            <horizontal_fov>1.0472</horizontal_fov>
            <image>
              <width>640</width>
              <height>480</height>
              <format>R8G8B8</format>
            </image>
            <clip>
              <near>0.05</near>
              <far>3</far>
            </clip>
          </camera>
          <plugin name='camera_plugin' filename='libgazebo_ros_openni_kinect.so'>
            <baseline>0.2</baseline>
            <alwaysOn>1</alwaysOn>
            <updateRate>0.0</updateRate>
            <cameraName>camera_ir</cameraName>
            <imageTopicName>/camera/color/image_raw</imageTopicName>
            <cameraInfoTopicName>/camera/color/camera_info</cameraInfoTopicName>
            <depthImageTopicName>/camera/depth/image_raw</depthImageTopicName>
            <depthImageCameraInfoTopicName>/camera/depth/camera_info</depthImageCameraInfoTopicName>
            <pointCloudTopicName>/camera/depth/points</pointCloudTopicName>
            <frameName>camera_link</frameName>
            <pointCloudCutoff>0.5</pointCloudCutoff>
            <pointCloudCutoffMax>3.0</pointCloudCutoffMax>
            <distortionK1>0</distortionK1>
            <distortionK2>0</distortionK2>
            <distortionK3>0</distortionK3>
            <distortionT1>0</distortionT1>
            <distortionT2>0</distortionT2>
            <CxPrime>0</CxPrime>
            <Cx>0</Cx>
            <Cy>0</Cy>
            <focalLength>0</focalLength>
            <hackBaseline>0</hackBaseline>
            <robotNamespace>/</robotNamespace>
          </plugin>
          <pose frame=''>0.3 0 0.5 0 -0 0</pose>
        </sensor>
        <velocity_decay/>
        <velocity_decay/>
        <sensor name='mirback_laser_link' type='ray'>
          <visualize>0</visualize>
          <update_rate>12.5</update_rate>
          <ray>
            <scan>
              <horizontal>
                <samples>541</samples>
                <resolution>1</resolution>
                <min_angle>-2.35619</min_angle>
                <max_angle>2.35619</max_angle>
              </horizontal>
              <vertical>
                <samples>1</samples>
                <min_angle>0</min_angle>
                <max_angle>0</max_angle>
              </vertical>
            </scan>
            <range>
              <min>0.05</min>
              <max>29</max>
              <resolution>0.01</resolution>
            </range>
            <noise>
              <type>gaussian</type>
              <mean>0</mean>
              <stddev>0.01</stddev>
            </noise>
          </ray>
          <plugin name='gazebo_ros_back_laser_link_controller' filename='libgazebo_ros_laser.so'>
            <frameName>back_laser_link</frameName>
            <topicName>b_scan</topicName>
            <robotNamespace>/</robotNamespace>
          </plugin>
          <pose frame=''>-0.3548 -0.2352 0.1914 0 0 -2.35619</pose>
        </sensor>
        <velocity_decay/>
        <sensor name='mirfront_laser_link' type='ray'>
          <visualize>0</visualize>
          <update_rate>12.5</update_rate>
          <ray>
            <scan>
              <horizontal>
                <samples>541</samples>
                <resolution>1</resolution>
                <min_angle>-2.35619</min_angle>
                <max_angle>2.35619</max_angle>
              </horizontal>
              <vertical>
                <samples>1</samples>
                <min_angle>0</min_angle>
                <max_angle>0</max_angle>
              </vertical>
            </scan>
            <range>
              <min>0.05</min>
              <max>29</max>
              <resolution>0.01</resolution>
            </range>
            <noise>
              <type>gaussian</type>
              <mean>0</mean>
              <stddev>0.01</stddev>
            </noise>
          </ray>
          <plugin name='gazebo_ros_front_laser_link_controller' filename='libgazebo_ros_laser.so'>
            <frameName>front_laser_link</frameName>
            <topicName>f_scan</topicName>
            <robotNamespace>/</robotNamespace>
          </plugin>
          <pose frame=''>0.4288 0.2358 0.1914 0 -0 0.785398</pose>
        </sensor>
        <gravity>1</gravity>
        <velocity_decay/>
        <gravity>1</gravity>
        <sensor name='imu_sensor' type='imu'>
          <always_on>1</always_on>
          <update_rate>100</update_rate>
          <visualize>1</visualize>
          <topic>__default_topic__</topic>
          <plugin name='imu_plugin' filename='libgazebo_ros_imu_sensor.so'>
            <topicName>imu_data</topicName>
            <bodyName>mirimu_link</bodyName>
            <updateRateHZ>50.0</updateRateHZ>
            <gaussianNoise>2.89e-08</gaussianNoise>
            <xyzOffset>0 0 0</xyzOffset>
            <rpyOffset>0 0 0</rpyOffset>
            <frameName>imu_frame</frameName>
            <robotNamespace>/</robotNamespace>
          </plugin>
          <pose frame=''>0 0 0.25 0 -0 0</pose>
          <imu/>
        </sensor>
        <self_collide>0</self_collide>
        <enable_wind>0</enable_wind>
        <kinematic>0</kinematic>
      </link>
      <link name='shoulder_link'>
        <pose frame=''>0.325 0 1.013 0 -0 3.14159</pose>
        <inertial>
          <pose frame=''>0 0 0 0 -0 0</pose>
          <mass>3.7</mass>
          <inertia>
            <ixx>0.0102675</ixx>
            <ixy>0</ixy>
            <ixz>0</ixz>
            <iyy>0.0102675</iyy>
            <iyz>0</iyz>
            <izz>0.00666</izz>
          </inertia>
        </inertial>
        <collision name='shoulder_link_collision'>
          <pose frame=''>0 0 0 0 -0 0</pose>
          <geometry>
            <mesh>
              <scale>1 1 1</scale>
              <uri>/home/larry/catkin_ws/src/sdl-packages/sdl_robot_description/urdf/meshes/ur5e/collision/shoulder.stl</uri>
            </mesh>
          </geometry>
          <surface>
            <contact>
              <ode/>
            </contact>
            <friction>
              <ode/>
              <torsional>
                <ode/>
              </torsional>
            </friction>
            <bounce/>
          </surface>
          <max_contacts>10</max_contacts>
        </collision>
        <visual name='shoulder_link_visual'>
          <pose frame=''>0 0 0 0 -0 0</pose>
          <geometry>
            <mesh>
              <scale>1 1 1</scale>
              <uri>/home/larry/catkin_ws/src/sdl-packages/sdl_robot_description/urdf/meshes/ur5e/visual/shoulder.dae</uri>
            </mesh>
          </geometry>
          <material>
            <script>
              <uri>__default__</uri>
              <name>__default__</name>
            </script>
          </material>
        </visual>
        <gravity>1</gravity>
        <velocity_decay/>
        <self_collide>1</self_collide>
        <enable_wind>0</enable_wind>
        <kinematic>0</kinematic>
      </link>
      <joint name='shoulder_pan_joint' type='revolute'>
        <child>shoulder_link</child>
        <parent>mirbase_footprint</parent>
        <axis>
          <xyz>-0 0 1</xyz>
          <limit>
            <lower>-3.14159</lower>
            <upper>3.14159</upper>
            <effort>150</effort>
            <velocity>3.14</velocity>
          </limit>
          <dynamics>
            <damping>0</damping>
            <friction>0</friction>
            <spring_reference>0</spring_reference>
            <spring_stiffness>0</spring_stiffness>
          </dynamics>
          <use_parent_model_frame>1</use_parent_model_frame>
        </axis>
      </joint>
      <link name='upper_arm_link'>
        <pose frame=''>0.325 -0.138 1.013 3e-06 1.57079 3.14159</pose>
        <inertial>
          <pose frame=''>0 0 0.2125 0 -0 0</pose>
          <mass>8.393</mass>
          <inertia>
            <ixx>0.133886</ixx>
            <ixy>0</ixy>
            <ixz>0</ixz>
            <iyy>0.133886</iyy>
            <iyz>0</iyz>
            <izz>0.0151074</izz>
          </inertia>
        </inertial>
        <collision name='upper_arm_link_collision'>
          <pose frame=''>0 0 0 0 -0 0</pose>
          <geometry>
            <mesh>
              <scale>1 1 1</scale>
              <uri>/home/larry/catkin_ws/src/sdl-packages/sdl_robot_description/urdf/meshes/ur5e/collision/upperarm.stl</uri>
            </mesh>
          </geometry>
          <surface>
            <contact>
              <ode/>
            </contact>
            <friction>
              <ode/>
              <torsional>
                <ode/>
              </torsional>
            </friction>
            <bounce/>
          </surface>
          <max_contacts>10</max_contacts>
        </collision>
        <visual name='upper_arm_link_visual'>
          <pose frame=''>0 0 0 0 -0 0</pose>
          <geometry>
            <mesh>
              <scale>1 1 1</scale>
              <uri>/home/larry/catkin_ws/src/sdl-packages/sdl_robot_description/urdf/meshes/ur5e/visual/upperarm.dae</uri>
            </mesh>
          </geometry>
          <material>
            <script>
              <uri>__default__</uri>
              <name>__default__</name>
            </script>
          </material>
        </visual>
        <gravity>1</gravity>
        <velocity_decay/>
        <self_collide>1</self_collide>
        <enable_wind>0</enable_wind>
        <kinematic>0</kinematic>
      </link>
      <joint name='shoulder_lift_joint' type='revolute'>
        <child>upper_arm_link</child>
        <parent>shoulder_link</parent>
        <axis>
          <xyz>-0 -1 0</xyz>
          <limit>
            <lower>-3.14159</lower>
            <upper>3.14159</upper>
            <effort>150</effort>
            <velocity>3.14</velocity>
          </limit>
          <dynamics>
            <damping>0</damping>
            <friction>0</friction>
            <spring_reference>0</spring_reference>
            <spring_stiffness>0</spring_stiffness>
          </dynamics>
          <use_parent_model_frame>1</use_parent_model_frame>
        </axis>
      </joint>
      <link name='forearm_link'>
        <pose frame=''>-0.1 -0.007 1.013 3e-06 1.57079 3.14159</pose>
        <inertial>
          <pose frame=''>0 0 0.196 0 -0 0</pose>
          <mass>2.275</mass>
          <inertia>
            <ixx>0.0311796</ixx>
            <ixy>0</ixy>
            <ixz>0</ixz>
            <iyy>0.0311796</iyy>
            <iyz>0</iyz>
            <izz>0.004095</izz>
          </inertia>
        </inertial>
        <collision name='forearm_link_collision'>
          <pose frame=''>0 0 0 0 -0 0</pose>
          <geometry>
            <mesh>
              <scale>1 1 1</scale>
              <uri>/home/larry/catkin_ws/src/sdl-packages/sdl_robot_description/urdf/meshes/ur5e/collision/forearm.stl</uri>
            </mesh>
          </geometry>
          <surface>
            <contact>
              <ode/>
            </contact>
            <friction>
              <ode/>
              <torsional>
                <ode/>
              </torsional>
            </friction>
            <bounce/>
          </surface>
          <max_contacts>10</max_contacts>
        </collision>
        <visual name='forearm_link_visual'>
          <pose frame=''>0 0 0 0 -0 0</pose>
          <geometry>
            <mesh>
              <scale>1 1 1</scale>
              <uri>/home/larry/catkin_ws/src/sdl-packages/sdl_robot_description/urdf/meshes/ur5e/visual/forearm.dae</uri>
            </mesh>
          </geometry>
          <material>
            <script>
              <uri>__default__</uri>
              <name>__default__</name>
            </script>
          </material>
        </visual>
        <gravity>1</gravity>
        <velocity_decay/>
        <self_collide>1</self_collide>
        <enable_wind>0</enable_wind>
        <kinematic>0</kinematic>
      </link>
      <joint name='elbow_joint' type='revolute'>
        <child>forearm_link</child>
        <parent>upper_arm_link</parent>
        <axis>
          <xyz>-0 -1 0</xyz>
          <limit>
            <lower>-3.14159</lower>
            <upper>3.14159</upper>
            <effort>150</effort>
            <velocity>3.14</velocity>
          </limit>
          <dynamics>
            <damping>0</damping>
            <friction>0</friction>
            <spring_reference>0</spring_reference>
            <spring_stiffness>0</spring_stiffness>
          </dynamics>
          <use_parent_model_frame>1</use_parent_model_frame>
        </axis>
      </joint>
      <link name='wrist_1_link'>
        <pose frame=''>-0.492 -0.007 1.013 -3.14159 0 0</pose>
        <inertial>
          <pose frame=''>0 0.127 0 0 -0 0</pose>
          <mass>1.219</mass>
          <inertia>
            <ixx>0.0025599</ixx>
            <ixy>0</ixy>
            <ixz>0</ixz>
            <iyy>0.0025599</iyy>
            <iyz>0</iyz>
            <izz>0.0021942</izz>
          </inertia>
        </inertial>
        <collision name='wrist_1_link_collision'>
          <pose frame=''>0 0 0 0 -0 0</pose>
          <geometry>
            <mesh>
              <scale>1 1 1</scale>
              <uri>/home/larry/catkin_ws/src/sdl-packages/sdl_robot_description/urdf/meshes/ur5e/collision/wrist1.stl</uri>
            </mesh>
          </geometry>
          <surface>
            <contact>
              <ode/>
            </contact>
            <friction>
              <ode/>
              <torsional>
                <ode/>
              </torsional>
            </friction>
            <bounce/>
          </surface>
          <max_contacts>10</max_contacts>
        </collision>
        <visual name='wrist_1_link_visual'>
          <pose frame=''>0 0 0 0 -0 0</pose>
          <geometry>
            <mesh>
              <scale>1 1 1</scale>
              <uri>/home/larry/catkin_ws/src/sdl-packages/sdl_robot_description/urdf/meshes/ur5e/visual/wrist1.dae</uri>
            </mesh>
          </geometry>
          <material>
            <script>
              <uri>__default__</uri>
              <name>__default__</name>
            </script>
          </material>
        </visual>
        <gravity>1</gravity>
        <velocity_decay/>
        <self_collide>1</self_collide>
        <enable_wind>0</enable_wind>
        <kinematic>0</kinematic>
      </link>
      <joint name='wrist_1_joint' type='revolute'>
        <child>wrist_1_link</child>
        <parent>forearm_link</parent>
        <axis>
          <xyz>-0 -1 -0</xyz>
          <limit>
            <lower>-3.14159</lower>
            <upper>3.14159</upper>
            <effort>28</effort>
            <velocity>6.28</velocity>
          </limit>
          <dynamics>
            <damping>0</damping>
            <friction>0</friction>
            <spring_reference>0</spring_reference>
            <spring_stiffness>0</spring_stiffness>
          </dynamics>
          <use_parent_model_frame>1</use_parent_model_frame>
        </axis>
      </joint>
      <link name='wrist_2_link'>
        <pose frame=''>-0.492 -0.134 1.013 -3.14159 0 0</pose>
        <inertial>
          <pose frame=''>0 0 0.1 0 -0 0</pose>
          <mass>1.219</mass>
          <inertia>
            <ixx>0.0025599</ixx>
            <ixy>0</ixy>
            <ixz>0</ixz>
            <iyy>0.0025599</iyy>
            <iyz>0</iyz>
            <izz>0.0021942</izz>
          </inertia>
        </inertial>
        <collision name='wrist_2_link_collision'>
          <pose frame=''>0 0 0 0 -0 0</pose>
          <geometry>
            <mesh>
              <scale>1 1 1</scale>
              <uri>/home/larry/catkin_ws/src/sdl-packages/sdl_robot_description/urdf/meshes/ur5e/collision/wrist2.stl</uri>
            </mesh>
          </geometry>
          <surface>
            <contact>
              <ode/>
            </contact>
            <friction>
              <ode/>
              <torsional>
                <ode/>
              </torsional>
            </friction>
            <bounce/>
          </surface>
          <max_contacts>10</max_contacts>
        </collision>
        <visual name='wrist_2_link_visual'>
          <pose frame=''>0 0 0 0 -0 0</pose>
          <geometry>
            <mesh>
              <scale>1 1 1</scale>
              <uri>/home/larry/catkin_ws/src/sdl-packages/sdl_robot_description/urdf/meshes/ur5e/visual/wrist2.dae</uri>
            </mesh>
          </geometry>
          <material>
            <script>
              <uri>__default__</uri>
              <name>__default__</name>
            </script>
          </material>
        </visual>
        <gravity>1</gravity>
        <velocity_decay/>
        <self_collide>1</self_collide>
        <enable_wind>0</enable_wind>
        <kinematic>0</kinematic>
      </link>
      <joint name='wrist_2_joint' type='revolute'>
        <child>wrist_2_link</child>
        <parent>wrist_1_link</parent>
        <axis>
          <xyz>-0 0 -1</xyz>
          <limit>
            <lower>-3.14159</lower>
            <upper>3.14159</upper>
            <effort>28</effort>
            <velocity>6.28</velocity>
          </limit>
          <dynamics>
            <damping>0</damping>
            <friction>0</friction>
            <spring_reference>0</spring_reference>
            <spring_stiffness>0</spring_stiffness>
          </dynamics>
          <use_parent_model_frame>1</use_parent_model_frame>
        </axis>
      </joint>
      <link name='wrist_3_link'>
        <pose frame=''>-0.492 -0.134 0.913 -3.14159 0 0</pose>
        <inertial>
          <pose frame=''>2e-06 0.106075 -0 1.5708 -0 0</pose>
          <mass>0.46442</mass>
          <inertia>
            <ixx>0.000584675</ixx>
            <ixy>-8.24373e-10</ixy>
            <ixz>-3.76259e-08</ixz>
            <iyy>0.000606405</iyy>
            <iyz>-9.86456e-10</iyz>
            <izz>0.000268897</izz>
          </inertia>
        </inertial>
        <collision name='wrist_3_link_collision'>
          <pose frame=''>0 0 0 0 -0 0</pose>
          <geometry>
            <mesh>
              <scale>1 1 1</scale>
              <uri>/home/larry/catkin_ws/src/sdl-packages/sdl_robot_description/urdf/meshes/ur5e/collision/wrist3.stl</uri>
            </mesh>
          </geometry>
          <surface>
            <contact>
              <ode/>
            </contact>
            <friction>
              <ode/>
              <torsional>
                <ode/>
              </torsional>
            </friction>
            <bounce/>
          </surface>
          <max_contacts>10</max_contacts>
        </collision>
        <collision name='wrist_3_link_fixed_joint_lump__ee_link_collision_1'>
          <pose frame=''>-0 0.09 0 0 -0 1.5708</pose>
          <geometry>
            <box>
              <size>0.01 0.01 0.01</size>
            </box>
          </geometry>
          <surface>
            <contact>
              <ode/>
            </contact>
            <friction>
              <ode/>
              <torsional>
                <ode/>
              </torsional>
            </friction>
            <bounce/>
          </surface>
          <max_contacts>10</max_contacts>
        </collision>
        <collision name='wrist_3_link_fixed_joint_lump__robotiq_arg2f_coupling_collision_2'>
          <pose frame=''>0 0.1 0 3.14159 1.57079 -1.57079</pose>
          <geometry>
            <mesh>
              <scale>0.001 0.001 0.001</scale>
              <uri>/home/larry/catkin_ws/src/sdl-packages/sdl_robot_description/urdf/meshes/robotiq_2f140/collision/robotiq_arg2f_coupling.stl</uri>
            </mesh>
          </geometry>
          <max_contacts>10</max_contacts>
          <surface>
            <contact>
              <ode/>
            </contact>
            <bounce/>
            <friction>
              <torsional>
                <ode/>
              </torsional>
              <ode/>
            </friction>
          </surface>
        </collision>
        <collision name='wrist_3_link_fixed_joint_lump__robotiq_arg2f_base_link_collision_3'>
          <pose frame=''>0 0.1 0 3.14159 1.57079 -1.57079</pose>
          <geometry>
            <mesh>
              <scale>1 1 1</scale>
              <uri>/home/larry/catkin_ws/src/sdl-packages/sdl_robot_description/urdf/meshes/robotiq_2f140/collision/robotiq_arg2f_base_link.stl</uri>
            </mesh>
          </geometry>
          <max_contacts>10</max_contacts>
          <surface>
            <contact>
              <ode/>
            </contact>
            <bounce/>
            <friction>
              <torsional>
                <ode/>
              </torsional>
              <ode/>
            </friction>
          </surface>
        </collision>
        <visual name='wrist_3_link_visual'>
          <pose frame=''>0 0 0 0 -0 0</pose>
          <geometry>
            <mesh>
              <scale>1 1 1</scale>
              <uri>/home/larry/catkin_ws/src/sdl-packages/sdl_robot_description/urdf/meshes/ur5e/visual/wrist3.dae</uri>
            </mesh>
          </geometry>
          <material>
            <script>
              <uri>__default__</uri>
              <name>__default__</name>
            </script>
          </material>
        </visual>
        <visual name='wrist_3_link_fixed_joint_lump__robotiq_arg2f_coupling_visual_1'>
          <pose frame=''>0 0.1 0 3.14159 1.57079 -1.57079</pose>
          <geometry>
            <mesh>
              <scale>0.001 0.001 0.001</scale>
              <uri>/home/larry/catkin_ws/src/sdl-packages/sdl_robot_description/urdf/meshes/robotiq_2f140/visual/robotiq_arg2f_coupling.stl</uri>
            </mesh>
          </geometry>
        </visual>
        <visual name='wrist_3_link_fixed_joint_lump__robotiq_arg2f_base_link_visual_2'>
          <pose frame=''>0 0.1 0 3.14159 1.57079 -1.57079</pose>
          <geometry>
            <mesh>
              <scale>1 1 1</scale>
              <uri>/home/larry/catkin_ws/src/sdl-packages/sdl_robot_description/urdf/meshes/robotiq_2f140/visual/robotiq_arg2f_base_link.stl</uri>
            </mesh>
          </geometry>
        </visual>
        <velocity_decay/>
        <gravity>1</gravity>
        <velocity_decay/>
        <self_collide>1</self_collide>
        <enable_wind>0</enable_wind>
        <kinematic>0</kinematic>
      </link>
      <joint name='wrist_3_joint' type='revolute'>
        <child>wrist_3_link</child>
        <parent>wrist_2_link</parent>
        <axis>
          <xyz>-0 -1 -0</xyz>
          <limit>
            <lower>-3.14159</lower>
            <upper>3.14159</upper>
            <effort>28</effort>
            <velocity>6.28</velocity>
          </limit>
          <dynamics>
            <damping>0</damping>
            <friction>0</friction>
            <spring_reference>0</spring_reference>
            <spring_stiffness>0</spring_stiffness>
          </dynamics>
          <use_parent_model_frame>1</use_parent_model_frame>
        </axis>
      </joint>
      <link name='left_outer_knuckle'>
        <pose frame=''>-0.461399 -0.288905 0.913 0.725003 -1.57079 3.14159</pose>
        <inertial>
          <pose frame=''>0.000164 0.04584 0.01178 0 -0 0</pose>
          <mass>0.0311462</mass>
          <inertia>
            <ixx>2.96016e-05</ixx>
            <ixy>-1.09755e-07</ixy>
            <ixz>7.40449e-08</ixz>
            <iyy>1.16215e-05</iyy>
            <iyz>1.08762e-05</iyz>
            <izz>2.07508e-05</izz>
          </inertia>
        </inertial>
        <collision name='left_outer_knuckle_collision'>
          <pose frame=''>0 0 0 0 -0 0</pose>
          <geometry>
            <mesh>
              <scale>1 1 1</scale>
              <uri>/home/larry/catkin_ws/src/sdl-packages/sdl_robot_description/urdf/meshes/robotiq_2f140/collision/robotiq_arg2f_140_outer_knuckle.stl</uri>
            </mesh>
          </geometry>
          <max_contacts>10</max_contacts>
          <surface>
            <contact>
              <ode/>
            </contact>
            <bounce/>
            <friction>
              <torsional>
                <ode/>
              </torsional>
              <ode/>
            </friction>
          </surface>
        </collision>
        <collision name='left_outer_knuckle_fixed_joint_lump__left_outer_finger_collision_1'>
          <pose frame=''>0 0.01822 0.026002 0 -0 0</pose>
          <geometry>
            <mesh>
              <scale>1 1 1</scale>
              <uri>/home/larry/catkin_ws/src/sdl-packages/sdl_robot_description/urdf/meshes/robotiq_2f140/collision/robotiq_arg2f_140_outer_finger.stl</uri>
            </mesh>
          </geometry>
          <max_contacts>10</max_contacts>
          <surface>
            <contact>
              <ode/>
            </contact>
            <bounce/>
            <friction>
              <torsional>
                <ode/>
              </torsional>
              <ode/>
            </friction>
          </surface>
        </collision>
        <visual name='left_outer_knuckle_visual'>
          <pose frame=''>0 0 0 0 -0 0</pose>
          <geometry>
            <mesh>
              <scale>1 1 1</scale>
              <uri>/home/larry/catkin_ws/src/sdl-packages/sdl_robot_description/urdf/meshes/robotiq_2f140/visual/robotiq_arg2f_140_outer_knuckle.stl</uri>
            </mesh>
          </geometry>
        </visual>
        <visual name='left_outer_knuckle_fixed_joint_lump__left_outer_finger_visual_1'>
          <pose frame=''>0 0.01822 0.026002 0 -0 0</pose>
          <geometry>
            <mesh>
              <scale>1 1 1</scale>
              <uri>/home/larry/catkin_ws/src/sdl-packages/sdl_robot_description/urdf/meshes/robotiq_2f140/visual/robotiq_arg2f_140_outer_finger.stl</uri>
            </mesh>
          </geometry>
        </visual>
        <self_collide>0</self_collide>
        <enable_wind>0</enable_wind>
        <kinematic>0</kinematic>
      </link>
      <joint name='finger_joint' type='revolute'>
        <child>left_outer_knuckle</child>
        <parent>wrist_3_link</parent>
        <axis>
          <xyz>-0 0 -1</xyz>
          <limit>
            <lower>0</lower>
            <upper>0.7</upper>
            <effort>1000</effort>
            <velocity>2</velocity>
          </limit>
          <dynamics>
            <spring_reference>0</spring_reference>
            <spring_stiffness>0</spring_stiffness>
          </dynamics>
          <use_parent_model_frame>1</use_parent_model_frame>
        </axis>
      </joint>
      <link name='left_inner_finger'>
        <pose frame=''>-0.396762 -0.365208 0.913 -3e-06 -1.57079 3.14159</pose>
        <inertial>
          <pose frame=''>0.0003 0.016008 -0.013695 0 -0 0</pose>
          <mass>0.0104003</mass>
          <inertia>
            <ixx>2.71909e-06</ixx>
            <ixy>1.35402e-21</ixy>
            <ixz>-7.18173e-22</ixz>
            <iyy>7.691e-07</iyy>
            <iyz>6.74715e-07</iyz>
            <izz>2.30315e-06</izz>
          </inertia>
        </inertial>
        <collision name='left_inner_finger_collision'>
          <pose frame=''>0 0 0 0 -0 0</pose>
          <geometry>
            <mesh>
              <scale>1 1 1</scale>
              <uri>/home/larry/catkin_ws/src/sdl-packages/sdl_robot_description/urdf/meshes/robotiq_2f140/collision/robotiq_arg2f_140_inner_finger.stl</uri>
            </mesh>
          </geometry>
          <max_contacts>10</max_contacts>
          <surface>
            <contact>
              <ode/>
            </contact>
            <bounce/>
            <friction>
              <torsional>
                <ode/>
              </torsional>
              <ode/>
            </friction>
          </surface>
        </collision>
        <collision name='left_inner_finger_pad_collision_1'>
          <pose frame=''>0 0.045755 -0.02722 0 -0 0</pose>
          <geometry>
            <box>
              <size>0.03 0.07 0.0075</size>
            </box>
          </geometry>
          <max_contacts>10</max_contacts>
          <surface>
            <contact>
              <ode/>
            </contact>
            <bounce/>
            <friction>
              <torsional>
                <ode/>
              </torsional>
              <ode/>
            </friction>
          </surface>
        </collision>
        <visual name='left_inner_finger_visual'>
          <pose frame=''>0 0 0 0 -0 0</pose>
          <geometry>
            <mesh>
              <scale>1 1 1</scale>
              <uri>/home/larry/catkin_ws/src/sdl-packages/sdl_robot_description/urdf/meshes/robotiq_2f140/visual/robotiq_arg2f_140_inner_finger.stl</uri>
            </mesh>
          </geometry>
        </visual>
        <visual name='left_inner_finger_pad_visual_1'>
          <pose frame=''>0 0.045755 -0.02722 0 -0 0</pose>
          <geometry>
            <box>
              <size>0.027 0.065 0.0075</size>
            </box>
          </geometry>
        </visual>
        <self_collide>0</self_collide>
        <enable_wind>0</enable_wind>
        <kinematic>0</kinematic>
      </link>
      <joint name='left_inner_finger_joint' type='revolute'>
        <child>left_inner_finger</child>
        <parent>left_outer_knuckle</parent>
        <axis>
          <xyz>0 -0 1</xyz>
          <limit>
            <lower>-0.8757</lower>
            <upper>0.8757</upper>
            <effort>1000</effort>
            <velocity>2</velocity>
          </limit>
          <dynamics>
            <spring_reference>0</spring_reference>
            <spring_stiffness>0</spring_stiffness>
          </dynamics>
          <use_parent_model_frame>1</use_parent_model_frame>
        </axis>
      </joint>
      <link name='left_inner_knuckle'>
        <pose frame=''>-0.4793 -0.29542 0.913 0.725003 -1.57079 3.14159</pose>
        <inertial>
          <pose frame=''>0.000123 0.050785 0.00104 0 -0 0</pose>
          <mass>0.0271177</mass>
          <inertia>
            <ixx>2.6191e-05</ixx>
            <ixy>-2.43617e-07</ixy>
            <ixz>-6.3779e-09</ixz>
            <iyy>2.82702e-06</iyy>
            <iyz>-5.37201e-07</iyz>
            <izz>2.83696e-05</izz>
          </inertia>
        </inertial>
        <collision name='left_inner_knuckle_collision'>
          <pose frame=''>0 0 0 0 -0 0</pose>
          <geometry>
            <mesh>
              <scale>1 1 1</scale>
              <uri>/home/larry/catkin_ws/src/sdl-packages/sdl_robot_description/urdf/meshes/robotiq_2f140/collision/robotiq_arg2f_140_inner_knuckle.stl</uri>
            </mesh>
          </geometry>
          <max_contacts>10</max_contacts>
          <surface>
            <contact>
              <ode/>
            </contact>
            <bounce/>
            <friction>
              <torsional>
                <ode/>
              </torsional>
              <ode/>
            </friction>
          </surface>
        </collision>
        <visual name='left_inner_knuckle_visual'>
          <pose frame=''>0 0 0 0 -0 0</pose>
          <geometry>
            <mesh>
              <scale>1 1 1</scale>
              <uri>/home/larry/catkin_ws/src/sdl-packages/sdl_robot_description/urdf/meshes/robotiq_2f140/visual/robotiq_arg2f_140_inner_knuckle.stl</uri>
            </mesh>
          </geometry>
        </visual>
        <self_collide>0</self_collide>
        <enable_wind>0</enable_wind>
        <kinematic>0</kinematic>
      </link>
      <joint name='left_inner_knuckle_joint' type='revolute'>
        <child>left_inner_knuckle</child>
        <parent>wrist_3_link</parent>
        <axis>
          <xyz>0 -0 1</xyz>
          <limit>
            <lower>-0.8757</lower>
            <upper>0.8757</upper>
            <effort>1000</effort>
            <velocity>2</velocity>
          </limit>
          <dynamics>
            <spring_reference>0</spring_reference>
            <spring_stiffness>0</spring_stiffness>
          </dynamics>
          <use_parent_model_frame>1</use_parent_model_frame>
        </axis>
      </joint>
      <link name='right_inner_knuckle'>
        <pose frame=''>-0.5047 -0.29542 0.913 0.725003 1.57079 3.14159</pose>
        <inertial>
          <pose frame=''>0.000123 0.050785 0.00104 0 -0 0</pose>
          <mass>0.0271177</mass>
          <inertia>
            <ixx>2.6191e-05</ixx>
            <ixy>-2.43617e-07</ixy>
            <ixz>-6.3779e-09</ixz>
            <iyy>2.82702e-06</iyy>
            <iyz>-5.37201e-07</iyz>
            <izz>2.83696e-05</izz>
          </inertia>
        </inertial>
        <collision name='right_inner_knuckle_collision'>
          <pose frame=''>0 0 0 0 -0 0</pose>
          <geometry>
            <mesh>
              <scale>1 1 1</scale>
              <uri>/home/larry/catkin_ws/src/sdl-packages/sdl_robot_description/urdf/meshes/robotiq_2f140/collision/robotiq_arg2f_140_inner_knuckle.stl</uri>
            </mesh>
          </geometry>
          <max_contacts>10</max_contacts>
          <surface>
            <contact>
              <ode/>
            </contact>
            <bounce/>
            <friction>
              <torsional>
                <ode/>
              </torsional>
              <ode/>
            </friction>
          </surface>
        </collision>
        <visual name='right_inner_knuckle_visual'>
          <pose frame=''>0 0 0 0 -0 0</pose>
          <geometry>
            <mesh>
              <scale>1 1 1</scale>
              <uri>/home/larry/catkin_ws/src/sdl-packages/sdl_robot_description/urdf/meshes/robotiq_2f140/visual/robotiq_arg2f_140_inner_knuckle.stl</uri>
            </mesh>
          </geometry>
        </visual>
        <self_collide>0</self_collide>
        <enable_wind>0</enable_wind>
        <kinematic>0</kinematic>
      </link>
      <joint name='right_inner_knuckle_joint' type='revolute'>
        <child>right_inner_knuckle</child>
        <parent>wrist_3_link</parent>
        <axis>
          <xyz>-0 0 -1</xyz>
          <limit>
            <lower>-0.8757</lower>
            <upper>0.8757</upper>
            <effort>1000</effort>
            <velocity>2</velocity>
          </limit>
          <dynamics>
            <spring_reference>0</spring_reference>
            <spring_stiffness>0</spring_stiffness>
          </dynamics>
          <use_parent_model_frame>1</use_parent_model_frame>
        </axis>
      </joint>
      <link name='right_outer_knuckle'>
        <pose frame=''>-0.522601 -0.288905 0.913 0.725003 1.57079 3.14159</pose>
        <inertial>
          <pose frame=''>0.000164 0.04584 0.01178 0 -0 0</pose>
          <mass>0.0311462</mass>
          <inertia>
            <ixx>2.96016e-05</ixx>
            <ixy>-1.09755e-07</ixy>
            <ixz>7.40449e-08</ixz>
            <iyy>1.16215e-05</iyy>
            <iyz>1.08762e-05</iyz>
            <izz>2.07508e-05</izz>
          </inertia>
        </inertial>
        <collision name='right_outer_knuckle_collision'>
          <pose frame=''>0 0 0 0 -0 0</pose>
          <geometry>
            <mesh>
              <scale>1 1 1</scale>
              <uri>/home/larry/catkin_ws/src/sdl-packages/sdl_robot_description/urdf/meshes/robotiq_2f140/collision/robotiq_arg2f_140_outer_knuckle.stl</uri>
            </mesh>
          </geometry>
          <max_contacts>10</max_contacts>
          <surface>
            <contact>
              <ode/>
            </contact>
            <bounce/>
            <friction>
              <torsional>
                <ode/>
              </torsional>
              <ode/>
            </friction>
          </surface>
        </collision>
        <collision name='right_outer_knuckle_fixed_joint_lump__right_outer_finger_collision_1'>
          <pose frame=''>0 0.01822 0.026002 0 -0 0</pose>
          <geometry>
            <mesh>
              <scale>1 1 1</scale>
              <uri>/home/larry/catkin_ws/src/sdl-packages/sdl_robot_description/urdf/meshes/robotiq_2f140/collision/robotiq_arg2f_140_outer_finger.stl</uri>
            </mesh>
          </geometry>
          <max_contacts>10</max_contacts>
          <surface>
            <contact>
              <ode/>
            </contact>
            <bounce/>
            <friction>
              <torsional>
                <ode/>
              </torsional>
              <ode/>
            </friction>
          </surface>
        </collision>
        <visual name='right_outer_knuckle_visual'>
          <pose frame=''>0 0 0 0 -0 0</pose>
          <geometry>
            <mesh>
              <scale>1 1 1</scale>
              <uri>/home/larry/catkin_ws/src/sdl-packages/sdl_robot_description/urdf/meshes/robotiq_2f140/visual/robotiq_arg2f_140_outer_knuckle.stl</uri>
            </mesh>
          </geometry>
        </visual>
        <visual name='right_outer_knuckle_fixed_joint_lump__right_outer_finger_visual_1'>
          <pose frame=''>0 0.01822 0.026002 0 -0 0</pose>
          <geometry>
            <mesh>
              <scale>1 1 1</scale>
              <uri>/home/larry/catkin_ws/src/sdl-packages/sdl_robot_description/urdf/meshes/robotiq_2f140/visual/robotiq_arg2f_140_outer_finger.stl</uri>
            </mesh>
          </geometry>
        </visual>
        <self_collide>0</self_collide>
        <enable_wind>0</enable_wind>
        <kinematic>0</kinematic>
      </link>
      <joint name='right_outer_knuckle_joint' type='revolute'>
        <child>right_outer_knuckle</child>
        <parent>wrist_3_link</parent>
        <axis>
          <xyz>-0 0 -1</xyz>
          <limit>
            <lower>-0.725</lower>
            <upper>0.725</upper>
            <effort>1000</effort>
            <velocity>2</velocity>
          </limit>
          <dynamics>
            <spring_reference>0</spring_reference>
            <spring_stiffness>0</spring_stiffness>
          </dynamics>
          <use_parent_model_frame>1</use_parent_model_frame>
        </axis>
      </joint>
      <link name='right_inner_finger'>
        <pose frame=''>-0.587238 -0.365208 0.913 -3e-06 1.57079 3.14159</pose>
        <inertial>
          <pose frame=''>0.0003 0.016008 -0.013695 0 -0 0</pose>
          <mass>0.0104003</mass>
          <inertia>
            <ixx>2.71909e-06</ixx>
            <ixy>1.35402e-21</ixy>
            <ixz>-7.18173e-22</ixz>
            <iyy>7.691e-07</iyy>
            <iyz>6.74715e-07</iyz>
            <izz>2.30315e-06</izz>
          </inertia>
        </inertial>
        <collision name='right_inner_finger_collision'>
          <pose frame=''>0 0 0 0 -0 0</pose>
          <geometry>
            <mesh>
              <scale>1 1 1</scale>
              <uri>/home/larry/catkin_ws/src/sdl-packages/sdl_robot_description/urdf/meshes/robotiq_2f140/collision/robotiq_arg2f_140_inner_finger.stl</uri>
            </mesh>
          </geometry>
          <max_contacts>10</max_contacts>
          <surface>
            <contact>
              <ode/>
            </contact>
            <bounce/>
            <friction>
              <torsional>
                <ode/>
              </torsional>
              <ode/>
            </friction>
          </surface>
        </collision>
        <collision name='right_inner_finger_pad_collision_1'>
          <pose frame=''>0 0.045755 -0.02722 0 -0 0</pose>
          <geometry>
            <box>
              <size>0.03 0.07 0.0075</size>
            </box>
          </geometry>
          <max_contacts>10</max_contacts>
          <surface>
            <contact>
              <ode/>
            </contact>
            <bounce/>
            <friction>
              <torsional>
                <ode/>
              </torsional>
              <ode/>
            </friction>
          </surface>
        </collision>
        <visual name='right_inner_finger_visual'>
          <pose frame=''>0 0 0 0 -0 0</pose>
          <geometry>
            <mesh>
              <scale>1 1 1</scale>
              <uri>/home/larry/catkin_ws/src/sdl-packages/sdl_robot_description/urdf/meshes/robotiq_2f140/visual/robotiq_arg2f_140_inner_finger.stl</uri>
            </mesh>
          </geometry>
        </visual>
        <visual name='right_inner_finger_pad_visual_1'>
          <pose frame=''>0 0.045755 -0.02722 0 -0 0</pose>
          <geometry>
            <box>
              <size>0.027 0.065 0.0075</size>
            </box>
          </geometry>
        </visual>
        <self_collide>0</self_collide>
        <enable_wind>0</enable_wind>
        <kinematic>0</kinematic>
      </link>
      <joint name='right_inner_finger_joint' type='revolute'>
        <child>right_inner_finger</child>
        <parent>right_outer_knuckle</parent>
        <axis>
          <xyz>-0 0 -1</xyz>
          <limit>
            <lower>-0.8757</lower>
            <upper>0.8757</upper>
            <effort>1000</effort>
            <velocity>2</velocity>
          </limit>
          <dynamics>
            <spring_reference>0</spring_reference>
            <spring_stiffness>0</spring_stiffness>
          </dynamics>
          <use_parent_model_frame>1</use_parent_model_frame>
        </axis>
      </joint>
      <link name='mirbl_caster_rotation_link'>
        <pose frame=''>-0.270154 0.203 0.1565 0 -0 0</pose>
        <inertial>
          <pose frame=''>0 0 -0.0425 0.418879 0 1.5708</pose>
          <mass>0.309754</mass>
          <inertia>
            <ixx>0.000584452</ixx>
            <ixy>0</ixy>
            <ixz>0</ixz>
            <iyy>0.000528726</iyy>
            <iyz>0</iyz>
            <izz>0.000179236</izz>
          </inertia>
        </inertial>
        <collision name='mirbl_caster_rotation_link_collision'>
          <pose frame=''>0 0 0 0 -0 0</pose>
          <geometry>
            <mesh>
              <scale>1 1 1</scale>
              <uri>/opt/ros/melodic/share/mir_description/meshes/collision/caster_wheel_base.stl</uri>
            </mesh>
          </geometry>
          <surface>
            <contact>
              <ode/>
            </contact>
            <friction>
              <ode/>
              <torsional>
                <ode/>
              </torsional>
            </friction>
            <bounce/>
          </surface>
          <max_contacts>10</max_contacts>
        </collision>
        <visual name='mirbl_caster_rotation_link_visual'>
          <pose frame=''>0 0 0 0 -0 0</pose>
          <geometry>
            <mesh>
              <scale>1 1 1</scale>
              <uri>/opt/ros/melodic/share/mir_description/meshes/visual/caster_wheel_base.stl</uri>
            </mesh>
          </geometry>
          <material>
            <script>
              <name>Gazebo/Grey</name>
              <uri>file://media/materials/scripts/gazebo.material</uri>
            </script>
          </material>
        </visual>
        <gravity>1</gravity>
        <velocity_decay/>
        <self_collide>0</self_collide>
        <enable_wind>0</enable_wind>
        <kinematic>0</kinematic>
      </link>
      <joint name='mirbl_caster_rotation_joint' type='revolute'>
        <child>mirbl_caster_rotation_link</child>
        <parent>mirbase_footprint</parent>
        <axis>
          <xyz>0 0 1</xyz>
          <limit>
            <lower>-1e+16</lower>
            <upper>1e+16</upper>
          </limit>
          <dynamics>
            <damping>0.01</damping>
            <friction>0</friction>
            <spring_reference>0</spring_reference>
            <spring_stiffness>0</spring_stiffness>
          </dynamics>
          <use_parent_model_frame>1</use_parent_model_frame>
        </axis>
      </joint>
      <link name='mirbl_caster_wheel_link'>
        <pose frame=''>-0.308354 0.203 0.0625 0 -0 0</pose>
        <inertial>
          <pose frame=''>0 0 0 1.5708 -0 0</pose>
          <mass>1</mass>
          <inertia>
            <ixx>0.0010619</ixx>
            <ixy>0</ixy>
            <ixz>0</ixz>
            <iyy>0.0010619</iyy>
            <iyz>0</iyz>
            <izz>0.00195312</izz>
          </inertia>
        </inertial>
        <collision name='mirbl_caster_wheel_link_collision'>
          <pose frame=''>0 0 0 0 -0 0</pose>
          <geometry>
            <mesh>
              <scale>1 1 1</scale>
              <uri>/opt/ros/melodic/share/mir_description/meshes/visual/wheel.stl</uri>
            </mesh>
          </geometry>
          <surface>
            <contact>
              <ode>
                <kp>1e+07</kp>
                <kd>1</kd>
                <min_depth>0.01</min_depth>
              </ode>
            </contact>
            <friction>
              <ode>
                <mu>1</mu>
                <mu2>1</mu2>
              </ode>
              <torsional>
                <ode/>
              </torsional>
            </friction>
            <bounce/>
          </surface>
          <max_contacts>10</max_contacts>
        </collision>
        <visual name='mirbl_caster_wheel_link_visual'>
          <pose frame=''>0 0 0 0 -0 0</pose>
          <geometry>
            <mesh>
              <scale>1 1 1</scale>
              <uri>/opt/ros/melodic/share/mir_description/meshes/visual/wheel.stl</uri>
            </mesh>
          </geometry>
          <material>
            <script>
              <name>Gazebo/DarkGrey</name>
              <uri>file://media/materials/scripts/gazebo.material</uri>
            </script>
          </material>
        </visual>
        <velocity_decay/>
        <gravity>1</gravity>
        <velocity_decay/>
        <self_collide>0</self_collide>
        <enable_wind>0</enable_wind>
        <kinematic>0</kinematic>
      </link>
      <joint name='mirbl_caster_wheel_joint' type='revolute'>
        <child>mirbl_caster_wheel_link</child>
        <parent>mirbl_caster_rotation_link</parent>
        <axis>
          <xyz>0 1 0</xyz>
          <limit>
            <lower>-1e+16</lower>
            <upper>1e+16</upper>
          </limit>
          <dynamics>
            <spring_reference>0</spring_reference>
            <spring_stiffness>0</spring_stiffness>
          </dynamics>
          <use_parent_model_frame>1</use_parent_model_frame>
        </axis>
      </joint>
      <link name='mirbr_caster_rotation_link'>
        <pose frame=''>-0.270154 -0.203 0.1565 0 -0 0</pose>
        <inertial>
          <pose frame=''>0 0 -0.0425 0.418879 0 1.5708</pose>
          <mass>0.309754</mass>
          <inertia>
            <ixx>0.000584452</ixx>
            <ixy>0</ixy>
            <ixz>0</ixz>
            <iyy>0.000528726</iyy>
            <iyz>0</iyz>
            <izz>0.000179236</izz>
          </inertia>
        </inertial>
        <collision name='mirbr_caster_rotation_link_collision'>
          <pose frame=''>0 0 0 0 -0 0</pose>
          <geometry>
            <mesh>
              <scale>1 1 1</scale>
              <uri>/opt/ros/melodic/share/mir_description/meshes/collision/caster_wheel_base.stl</uri>
            </mesh>
          </geometry>
          <surface>
            <contact>
              <ode/>
            </contact>
            <friction>
              <ode/>
              <torsional>
                <ode/>
              </torsional>
            </friction>
            <bounce/>
          </surface>
          <max_contacts>10</max_contacts>
        </collision>
        <visual name='mirbr_caster_rotation_link_visual'>
          <pose frame=''>0 0 0 0 -0 0</pose>
          <geometry>
            <mesh>
              <scale>1 1 1</scale>
              <uri>/opt/ros/melodic/share/mir_description/meshes/visual/caster_wheel_base.stl</uri>
            </mesh>
          </geometry>
          <material>
            <script>
              <name>Gazebo/Grey</name>
              <uri>file://media/materials/scripts/gazebo.material</uri>
            </script>
          </material>
        </visual>
        <gravity>1</gravity>
        <velocity_decay/>
        <self_collide>0</self_collide>
        <enable_wind>0</enable_wind>
        <kinematic>0</kinematic>
      </link>
      <joint name='mirbr_caster_rotation_joint' type='revolute'>
        <child>mirbr_caster_rotation_link</child>
        <parent>mirbase_footprint</parent>
        <axis>
          <xyz>0 0 1</xyz>
          <limit>
            <lower>-1e+16</lower>
            <upper>1e+16</upper>
          </limit>
          <dynamics>
            <damping>0.01</damping>
            <friction>0</friction>
            <spring_reference>0</spring_reference>
            <spring_stiffness>0</spring_stiffness>
          </dynamics>
          <use_parent_model_frame>1</use_parent_model_frame>
        </axis>
      </joint>
      <link name='mirbr_caster_wheel_link'>
        <pose frame=''>-0.308354 -0.203 0.0625 0 -0 0</pose>
        <inertial>
          <pose frame=''>0 0 0 1.5708 -0 0</pose>
          <mass>1</mass>
          <inertia>
            <ixx>0.0010619</ixx>
            <ixy>0</ixy>
            <ixz>0</ixz>
            <iyy>0.0010619</iyy>
            <iyz>0</iyz>
            <izz>0.00195312</izz>
          </inertia>
        </inertial>
        <collision name='mirbr_caster_wheel_link_collision'>
          <pose frame=''>0 0 0 0 -0 0</pose>
          <geometry>
            <mesh>
              <scale>1 1 1</scale>
              <uri>/opt/ros/melodic/share/mir_description/meshes/visual/wheel.stl</uri>
            </mesh>
          </geometry>
          <surface>
            <contact>
              <ode>
                <kp>1e+07</kp>
                <kd>1</kd>
                <min_depth>0.01</min_depth>
              </ode>
            </contact>
            <friction>
              <ode>
                <mu>1</mu>
                <mu2>1</mu2>
              </ode>
              <torsional>
                <ode/>
              </torsional>
            </friction>
            <bounce/>
          </surface>
          <max_contacts>10</max_contacts>
        </collision>
        <visual name='mirbr_caster_wheel_link_visual'>
          <pose frame=''>0 0 0 0 -0 0</pose>
          <geometry>
            <mesh>
              <scale>1 1 1</scale>
              <uri>/opt/ros/melodic/share/mir_description/meshes/visual/wheel.stl</uri>
            </mesh>
          </geometry>
          <material>
            <script>
              <name>Gazebo/DarkGrey</name>
              <uri>file://media/materials/scripts/gazebo.material</uri>
            </script>
          </material>
        </visual>
        <velocity_decay/>
        <gravity>1</gravity>
        <velocity_decay/>
        <self_collide>0</self_collide>
        <enable_wind>0</enable_wind>
        <kinematic>0</kinematic>
      </link>
      <joint name='mirbr_caster_wheel_joint' type='revolute'>
        <child>mirbr_caster_wheel_link</child>
        <parent>mirbr_caster_rotation_link</parent>
        <axis>
          <xyz>0 1 0</xyz>
          <limit>
            <lower>-1e+16</lower>
            <upper>1e+16</upper>
          </limit>
          <dynamics>
            <spring_reference>0</spring_reference>
            <spring_stiffness>0</spring_stiffness>
          </dynamics>
          <use_parent_model_frame>1</use_parent_model_frame>
        </axis>
      </joint>
      <link name='mirfl_caster_rotation_link'>
        <pose frame=''>0.341346 0.203 0.1565 0 -0 0</pose>
        <inertial>
          <pose frame=''>0 0 -0.0425 0.418879 0 1.5708</pose>
          <mass>0.309754</mass>
          <inertia>
            <ixx>0.000584452</ixx>
            <ixy>0</ixy>
            <ixz>0</ixz>
            <iyy>0.000528726</iyy>
            <iyz>0</iyz>
            <izz>0.000179236</izz>
          </inertia>
        </inertial>
        <collision name='mirfl_caster_rotation_link_collision'>
          <pose frame=''>0 0 0 0 -0 0</pose>
          <geometry>
            <mesh>
              <scale>1 1 1</scale>
              <uri>/opt/ros/melodic/share/mir_description/meshes/collision/caster_wheel_base.stl</uri>
            </mesh>
          </geometry>
          <surface>
            <contact>
              <ode/>
            </contact>
            <friction>
              <ode/>
              <torsional>
                <ode/>
              </torsional>
            </friction>
            <bounce/>
          </surface>
          <max_contacts>10</max_contacts>
        </collision>
        <visual name='mirfl_caster_rotation_link_visual'>
          <pose frame=''>0 0 0 0 -0 0</pose>
          <geometry>
            <mesh>
              <scale>1 1 1</scale>
              <uri>/opt/ros/melodic/share/mir_description/meshes/visual/caster_wheel_base.stl</uri>
            </mesh>
          </geometry>
          <material>
            <script>
              <name>Gazebo/Grey</name>
              <uri>file://media/materials/scripts/gazebo.material</uri>
            </script>
          </material>
        </visual>
        <gravity>1</gravity>
        <velocity_decay/>
        <self_collide>0</self_collide>
        <enable_wind>0</enable_wind>
        <kinematic>0</kinematic>
      </link>
      <joint name='mirfl_caster_rotation_joint' type='revolute'>
        <child>mirfl_caster_rotation_link</child>
        <parent>mirbase_footprint</parent>
        <axis>
          <xyz>0 0 1</xyz>
          <limit>
            <lower>-1e+16</lower>
            <upper>1e+16</upper>
          </limit>
          <dynamics>
            <damping>0.01</damping>
            <friction>0</friction>
            <spring_reference>0</spring_reference>
            <spring_stiffness>0</spring_stiffness>
          </dynamics>
          <use_parent_model_frame>1</use_parent_model_frame>
        </axis>
      </joint>
      <link name='mirfl_caster_wheel_link'>
        <pose frame=''>0.303146 0.203 0.0625 0 -0 0</pose>
        <inertial>
          <pose frame=''>0 0 0 1.5708 -0 0</pose>
          <mass>1</mass>
          <inertia>
            <ixx>0.0010619</ixx>
            <ixy>0</ixy>
            <ixz>0</ixz>
            <iyy>0.0010619</iyy>
            <iyz>0</iyz>
            <izz>0.00195312</izz>
          </inertia>
        </inertial>
        <collision name='mirfl_caster_wheel_link_collision'>
          <pose frame=''>0 0 0 0 -0 0</pose>
          <geometry>
            <mesh>
              <scale>1 1 1</scale>
              <uri>/opt/ros/melodic/share/mir_description/meshes/visual/wheel.stl</uri>
            </mesh>
          </geometry>
          <surface>
            <contact>
              <ode>
                <kp>1e+07</kp>
                <kd>1</kd>
                <min_depth>0.01</min_depth>
              </ode>
            </contact>
            <friction>
              <ode>
                <mu>1</mu>
                <mu2>1</mu2>
              </ode>
              <torsional>
                <ode/>
              </torsional>
            </friction>
            <bounce/>
          </surface>
          <max_contacts>10</max_contacts>
        </collision>
        <visual name='mirfl_caster_wheel_link_visual'>
          <pose frame=''>0 0 0 0 -0 0</pose>
          <geometry>
            <mesh>
              <scale>1 1 1</scale>
              <uri>/opt/ros/melodic/share/mir_description/meshes/visual/wheel.stl</uri>
            </mesh>
          </geometry>
          <material>
            <script>
              <name>Gazebo/DarkGrey</name>
              <uri>file://media/materials/scripts/gazebo.material</uri>
            </script>
          </material>
        </visual>
        <velocity_decay/>
        <gravity>1</gravity>
        <velocity_decay/>
        <self_collide>0</self_collide>
        <enable_wind>0</enable_wind>
        <kinematic>0</kinematic>
      </link>
      <joint name='mirfl_caster_wheel_joint' type='revolute'>
        <child>mirfl_caster_wheel_link</child>
        <parent>mirfl_caster_rotation_link</parent>
        <axis>
          <xyz>0 1 0</xyz>
          <limit>
            <lower>-1e+16</lower>
            <upper>1e+16</upper>
          </limit>
          <dynamics>
            <spring_reference>0</spring_reference>
            <spring_stiffness>0</spring_stiffness>
          </dynamics>
          <use_parent_model_frame>1</use_parent_model_frame>
        </axis>
      </joint>
      <link name='mirfr_caster_rotation_link'>
        <pose frame=''>0.341346 -0.203 0.1565 0 -0 0</pose>
        <inertial>
          <pose frame=''>0 0 -0.0425 0.418879 0 1.5708</pose>
          <mass>0.309754</mass>
          <inertia>
            <ixx>0.000584452</ixx>
            <ixy>0</ixy>
            <ixz>0</ixz>
            <iyy>0.000528726</iyy>
            <iyz>0</iyz>
            <izz>0.000179236</izz>
          </inertia>
        </inertial>
        <collision name='mirfr_caster_rotation_link_collision'>
          <pose frame=''>0 0 0 0 -0 0</pose>
          <geometry>
            <mesh>
              <scale>1 1 1</scale>
              <uri>/opt/ros/melodic/share/mir_description/meshes/collision/caster_wheel_base.stl</uri>
            </mesh>
          </geometry>
          <surface>
            <contact>
              <ode/>
            </contact>
            <friction>
              <ode/>
              <torsional>
                <ode/>
              </torsional>
            </friction>
            <bounce/>
          </surface>
          <max_contacts>10</max_contacts>
        </collision>
        <visual name='mirfr_caster_rotation_link_visual'>
          <pose frame=''>0 0 0 0 -0 0</pose>
          <geometry>
            <mesh>
              <scale>1 1 1</scale>
              <uri>/opt/ros/melodic/share/mir_description/meshes/visual/caster_wheel_base.stl</uri>
            </mesh>
          </geometry>
          <material>
            <script>
              <name>Gazebo/Grey</name>
              <uri>file://media/materials/scripts/gazebo.material</uri>
            </script>
          </material>
        </visual>
        <gravity>1</gravity>
        <velocity_decay/>
        <self_collide>0</self_collide>
        <enable_wind>0</enable_wind>
        <kinematic>0</kinematic>
      </link>
      <joint name='mirfr_caster_rotation_joint' type='revolute'>
        <child>mirfr_caster_rotation_link</child>
        <parent>mirbase_footprint</parent>
        <axis>
          <xyz>0 0 1</xyz>
          <limit>
            <lower>-1e+16</lower>
            <upper>1e+16</upper>
          </limit>
          <dynamics>
            <damping>0.01</damping>
            <friction>0</friction>
            <spring_reference>0</spring_reference>
            <spring_stiffness>0</spring_stiffness>
          </dynamics>
          <use_parent_model_frame>1</use_parent_model_frame>
        </axis>
      </joint>
      <link name='mirfr_caster_wheel_link'>
        <pose frame=''>0.303146 -0.203 0.0625 0 -0 0</pose>
        <inertial>
          <pose frame=''>0 0 0 1.5708 -0 0</pose>
          <mass>1</mass>
          <inertia>
            <ixx>0.0010619</ixx>
            <ixy>0</ixy>
            <ixz>0</ixz>
            <iyy>0.0010619</iyy>
            <iyz>0</iyz>
            <izz>0.00195312</izz>
          </inertia>
        </inertial>
        <collision name='mirfr_caster_wheel_link_collision'>
          <pose frame=''>0 0 0 0 -0 0</pose>
          <geometry>
            <mesh>
              <scale>1 1 1</scale>
              <uri>/opt/ros/melodic/share/mir_description/meshes/visual/wheel.stl</uri>
            </mesh>
          </geometry>
          <surface>
            <contact>
              <ode>
                <kp>1e+07</kp>
                <kd>1</kd>
                <min_depth>0.01</min_depth>
              </ode>
            </contact>
            <friction>
              <ode>
                <mu>1</mu>
                <mu2>1</mu2>
              </ode>
              <torsional>
                <ode/>
              </torsional>
            </friction>
            <bounce/>
          </surface>
          <max_contacts>10</max_contacts>
        </collision>
        <visual name='mirfr_caster_wheel_link_visual'>
          <pose frame=''>0 0 0 0 -0 0</pose>
          <geometry>
            <mesh>
              <scale>1 1 1</scale>
              <uri>/opt/ros/melodic/share/mir_description/meshes/visual/wheel.stl</uri>
            </mesh>
          </geometry>
          <material>
            <script>
              <name>Gazebo/DarkGrey</name>
              <uri>file://media/materials/scripts/gazebo.material</uri>
            </script>
          </material>
        </visual>
        <velocity_decay/>
        <gravity>1</gravity>
        <velocity_decay/>
        <self_collide>0</self_collide>
        <enable_wind>0</enable_wind>
        <kinematic>0</kinematic>
      </link>
      <joint name='mirfr_caster_wheel_joint' type='revolute'>
        <child>mirfr_caster_wheel_link</child>
        <parent>mirfr_caster_rotation_link</parent>
        <axis>
          <xyz>0 1 0</xyz>
          <limit>
            <lower>-1e+16</lower>
            <upper>1e+16</upper>
          </limit>
          <dynamics>
            <spring_reference>0</spring_reference>
            <spring_stiffness>0</spring_stiffness>
          </dynamics>
          <use_parent_model_frame>1</use_parent_model_frame>
        </axis>
      </joint>
      <link name='mirleft_wheel_link'>
        <pose frame=''>0 0.222604 0.0625 0 -0 0</pose>
        <inertial>
          <pose frame=''>0 0 0 1.5708 -0 0</pose>
          <mass>1</mass>
          <inertia>
            <ixx>0.0010619</ixx>
            <ixy>0</ixy>
            <ixz>0</ixz>
            <iyy>0.0010619</iyy>
            <iyz>0</iyz>
            <izz>0.00195312</izz>
          </inertia>
        </inertial>
        <collision name='mirleft_wheel_link_collision'>
          <pose frame=''>0 0 0 0 -0 0</pose>
          <geometry>
            <cylinder>
              <length>0.1</length>
              <radius>0.0625</radius>
            </cylinder>
          </geometry>
          <surface>
            <contact>
              <ode>
                <kp>1e+07</kp>
                <kd>1</kd>
                <min_depth>0.01</min_depth>
              </ode>
            </contact>
            <friction>
              <ode>
                <mu>200</mu>
                <mu2>200</mu2>
              </ode>
              <torsional>
                <ode/>
              </torsional>
            </friction>
            <bounce/>
          </surface>
          <max_contacts>10</max_contacts>
        </collision>
        <visual name='mirleft_wheel_link_visual'>
          <pose frame=''>0 0 0 0 -0 0</pose>
          <geometry>
            <mesh>
              <scale>1 1 1</scale>
              <uri>/opt/ros/melodic/share/mir_description/meshes/visual/wheel.stl</uri>
            </mesh>
          </geometry>
          <material>
            <script>
              <name>Gazebo/DarkGrey</name>
              <uri>file://media/materials/scripts/gazebo.material</uri>
            </script>
          </material>
        </visual>
        <velocity_decay/>
        <gravity>1</gravity>
        <velocity_decay/>
        <self_collide>0</self_collide>
        <enable_wind>0</enable_wind>
        <kinematic>0</kinematic>
      </link>
      <joint name='mirleft_wheel_joint' type='revolute'>
        <child>mirleft_wheel_link</child>
        <parent>mirbase_footprint</parent>
        <axis>
          <xyz>0 1 0</xyz>
          <limit>
            <lower>-1e+16</lower>
            <upper>1e+16</upper>
          </limit>
          <dynamics>
            <spring_reference>0</spring_reference>
            <spring_stiffness>0</spring_stiffness>
          </dynamics>
          <use_parent_model_frame>1</use_parent_model_frame>
        </axis>
      </joint>
      <link name='mirright_wheel_link'>
        <pose frame=''>0 -0.222604 0.0625 0 -0 0</pose>
        <inertial>
          <pose frame=''>0 0 0 1.5708 -0 0</pose>
          <mass>1</mass>
          <inertia>
            <ixx>0.0010619</ixx>
            <ixy>0</ixy>
            <ixz>0</ixz>
            <iyy>0.0010619</iyy>
            <iyz>0</iyz>
            <izz>0.00195312</izz>
          </inertia>
        </inertial>
        <collision name='mirright_wheel_link_collision'>
          <pose frame=''>0 0 0 0 -0 0</pose>
          <geometry>
            <cylinder>
              <length>0.1</length>
              <radius>0.0625</radius>
            </cylinder>
          </geometry>
          <surface>
            <contact>
              <ode>
                <kp>1e+07</kp>
                <kd>1</kd>
                <min_depth>0.01</min_depth>
              </ode>
            </contact>
            <friction>
              <ode>
                <mu>200</mu>
                <mu2>200</mu2>
              </ode>
              <torsional>
                <ode/>
              </torsional>
            </friction>
            <bounce/>
          </surface>
          <max_contacts>10</max_contacts>
        </collision>
        <visual name='mirright_wheel_link_visual'>
          <pose frame=''>0 0 0 0 -0 0</pose>
          <geometry>
            <mesh>
              <scale>1 1 1</scale>
              <uri>/opt/ros/melodic/share/mir_description/meshes/visual/wheel.stl</uri>
            </mesh>
          </geometry>
          <material>
            <script>
              <name>Gazebo/DarkGrey</name>
              <uri>file://media/materials/scripts/gazebo.material</uri>
            </script>
          </material>
        </visual>
        <velocity_decay/>
        <gravity>1</gravity>
        <velocity_decay/>
        <self_collide>0</self_collide>
        <enable_wind>0</enable_wind>
        <kinematic>0</kinematic>
      </link>
      <joint name='mirright_wheel_joint' type='revolute'>
        <child>mirright_wheel_link</child>
        <parent>mirbase_footprint</parent>
        <axis>
          <xyz>0 1 0</xyz>
          <limit>
            <lower>-1e+16</lower>
            <upper>1e+16</upper>
          </limit>
          <dynamics>
            <spring_reference>0</spring_reference>
            <spring_stiffness>0</spring_stiffness>
          </dynamics>
          <use_parent_model_frame>1</use_parent_model_frame>
        </axis>
      </joint>
      <plugin name='ros_control' filename='libgazebo_ros_control.so'>
        <robotNamespace>/</robotNamespace>
      </plugin>
      <plugin name='p3d_base_controller' filename='libgazebo_ros_p3d.so'>
        <alwaysOn>1</alwaysOn>
        <updateRate>50.0</updateRate>
        <bodyName>mirbase_footprint</bodyName>
        <topicName>base_pose_ground_truth</topicName>
        <gaussianNoise>0.01</gaussianNoise>
        <frameName>map</frameName>
        <xyzOffsets>0 0 0</xyzOffsets>
        <rpyOffsets>0 0 0</rpyOffsets>
        <robotNamespace>/</robotNamespace>
      </plugin>
      <static>0</static>
      <plugin name='mimic_robotiq_140_4' filename='libroboticsgroup_gazebo_mimic_joint_plugin.so'>
        <joint>finger_joint</joint>
        <mimicJoint>right_outer_knuckle_joint</mimicJoint>
        <multiplier>-1.0</multiplier>
        <robotNamespace>/</robotNamespace>
      </plugin>
      <plugin name='mimic_robotiq_140_2' filename='libroboticsgroup_gazebo_mimic_joint_plugin.so'>
        <joint>finger_joint</joint>
        <mimicJoint>left_inner_finger_joint</mimicJoint>
        <multiplier>1.0</multiplier>
        <robotNamespace>/</robotNamespace>
      </plugin>
      <plugin name='mimic_robotiq_140_1' filename='libroboticsgroup_gazebo_mimic_joint_plugin.so'>
        <joint>finger_joint</joint>
        <mimicJoint>right_inner_finger_joint</mimicJoint>
        <multiplier>1.0</multiplier>
        <robotNamespace>/</robotNamespace>
      </plugin>
      <plugin name='mimic_robotiq_140_3' filename='libroboticsgroup_gazebo_mimic_joint_plugin.so'>
        <joint>finger_joint</joint>
        <mimicJoint>left_inner_knuckle_joint</mimicJoint>
        <multiplier>-1.0</multiplier>
        <robotNamespace>/</robotNamespace>
      </plugin>
      <plugin name='mimic_robotiq_140_5' filename='libroboticsgroup_gazebo_mimic_joint_plugin.so'>
        <joint>finger_joint</joint>
        <mimicJoint>right_inner_knuckle_joint</mimicJoint>
        <multiplier>-1.0</multiplier>
        <robotNamespace>/</robotNamespace>
      </plugin>
      <pose frame=''>0 0 0.1 0 -0 0</pose>
    </model>
    <model name='apartment'>
      <static>1</static>
      <link name='link'>
        <collision name='collision'>
          <geometry>
            <mesh>
              <uri>model://apartment/meshes/apartment.dae</uri>
            </mesh>
          </geometry>
          <max_contacts>10</max_contacts>
          <surface>
            <contact>
              <ode/>
            </contact>
            <bounce/>
            <friction>
              <torsional>
                <ode/>
              </torsional>
              <ode/>
            </friction>
          </surface>
        </collision>
        <visual name='visual'>
          <geometry>
            <mesh>
              <uri>model://apartment/meshes/apartment.dae</uri>
            </mesh>
          </geometry>
        </visual>
        <self_collide>0</self_collide>
        <enable_wind>0</enable_wind>
        <kinematic>0</kinematic>
      </link>
      <pose frame=''>-4.14243 1.86519 0 0 -0 0</pose>
    </model>
    <state world_name='default'>
      <sim_time>39 74000000</sim_time>
      <real_time>255 578958939</real_time>
      <wall_time>1626107821 444428566</wall_time>
      <iterations>39074</iterations>
      <model name='apartment'>
        <pose frame=''>-4.14243 1.86519 0 0 -0 0</pose>
        <scale>1 1 1</scale>
        <link name='link'>
          <pose frame=''>-4.14243 1.86519 0 0 -0 0</pose>
          <velocity>0 0 0 0 -0 0</velocity>
          <acceleration>0 0 0 0 -0 0</acceleration>
          <wrench>0 0 0 0 -0 0</wrench>
        </link>
      </model>
      <model name='ground_plane'>
        <pose frame=''>0 0 0 0 -0 0</pose>
        <scale>1 1 1</scale>
        <link name='link'>
          <pose frame=''>0 0 0 0 -0 0</pose>
          <velocity>0 0 0 0 -0 0</velocity>
          <acceleration>0 0 0 0 -0 0</acceleration>
          <wrench>0 0 0 0 -0 0</wrench>
        </link>
      </model>
      <model name='robot'>
        <pose frame=''>3.30885 -2.45241 0.085244 0.416479 -0.052149 0.18905</pose>
        <scale>1 1 1</scale>
        <link name='forearm_link'>
          <pose frame=''>3.24168 -2.8889 1.00229 -1.69872 1.1508 1.64273</pose>
          <velocity>0.002345 0.011557 -0.010377 -0.152857 -0.023654 -0.0318</velocity>
          <acceleration>8.67838 30.4914 -38.97 -0.67304 -0.356793 2.87872</acceleration>
          <wrench>19.7433 69.3679 -88.6567 0 -0 0</wrench>
        </link>
        <link name='left_inner_finger'>
          <pose frame=''>3.01644 -3.22419 0.750186 -0.671928 -1.15191 -1.48576</pose>
          <velocity>-0.007401 -0.065563 0.312663 -2.28703 0.32264 2.06616</velocity>
          <acceleration>-0.210599 -130.376 622.022 -1.59199 0.333677 0.929683</acceleration>
          <wrench>-0.00219 -1.35595 6.46922 0 -0 0</wrench>
        </link>
        <link name='left_inner_knuckle'>
          <pose frame=''>2.92213 -3.17719 0.774499 -1.58881 -1.15085 -1.49988</pose>
          <velocity>-0.003858 -0.039644 0.065354 -0.135632 0.062493 0.016049</velocity>
          <acceleration>8.80778 -85.7571 113.132 0.239662 -0.920103 2.73964</acceleration>
          <wrench>0.238847 -2.32554 3.06789 0 -0 0</wrench>
        </link>
        <link name='left_outer_knuckle'>
          <pose frame=''>2.93844 -3.16799 0.777803 -0.720948 -1.15077 -1.49701</pose>
          <velocity>-0.004378 -0.052836 0.237626 -0.115963 -0.667869 -0.301124</velocity>
          <acceleration>20.0381 -129.759 522.634 1.81779 1.24623 2.25892</acceleration>
          <wrench>0.624111 -4.04149 16.2781 0 -0 0</wrench>
        </link>
        <link name='mirbase_footprint'>
          <pose frame=''>3.30885 -2.45241 0.085244 0.416479 -0.052149 0.18905</pose>
          <velocity>-0.000911 -3.7e-05 -0.004896 0.004124 -0.002541 -0.002124</velocity>
          <acceleration>-1.15559 -1.06749 -3.72479 0.369061 -0.643665 -0.735302</acceleration>
          <wrench>-83.2025 -76.8592 -268.185 0 -0 0</wrench>
        </link>
        <link name='mirbl_caster_rotation_link'>
          <pose frame=''>3.00935 -2.38516 0.296101 0.000601 -0.419547 1.64108</pose>
          <velocity>-0.001457 -0.000519 -0.005459 0.002502 -0.014292 0.025511</velocity>
          <acceleration>-1.06567 -0.799454 -3.95459 -2.79497 -1.01638 -0.265003</acceleration>
          <wrench>-0.330096 -0.247634 -1.22495 0 -0 0</wrench>
        </link>
        <link name='mirbl_caster_wheel_link'>
          <pose frame=''>3.00906 -2.38177 0.194693 0.000553 0.108341 1.64138</pose>
          <velocity>-0.00011 -0.000173 -0.005458 -1.01375 -0.973436 0.032449</velocity>
          <acceleration>-0.464286 -0.747437 -3.93778 0.594358 1.38219 1.30194</acceleration>
          <wrench>-0.464286 -0.747437 -3.93778 0 -0 0</wrench>
        </link>
        <link name='mirbr_caster_rotation_link'>
          <pose frame=''>3.08754 -2.74823 0.132082 0.05064 0.416705 -1.37445</pose>
          <velocity>-0.001718 0.000183 -0.004296 0.0632 -0.009897 0.008952</velocity>
          <acceleration>-0.983253 1.19013 -1.60574 2.17211 0.17175 -1.49697</acceleration>
          <wrench>-0.304567 0.368647 -0.497385 0 -0 0</wrench>
        </link>
        <link name='mirbr_caster_wheel_link'>
          <pose frame=''>3.07797 -2.67577 0.061696 3.07946 -0.729463 1.78803</pose>
          <velocity>-0.001806 0.00197 -0.000871 -0.032086 -0.029279 0.000703</velocity>
          <acceleration>-1.47171 0.660937 -0.092369 -2.59687 1.56705 0.731732</acceleration>
          <wrench>-1.47171 0.660937 -0.092369 0 -0 0</wrench>
        </link>
        <link name='mirfl_caster_rotation_link'>
          <pose frame=''>3.60914 -2.2704 0.327976 0.000662 -0.419549 1.64093</pose>
          <velocity>-0.001289 -0.001954 -0.003454 0.002089 -0.015841 0.028831</velocity>
          <acceleration>-0.998997 -1.32385 -3.48486 2.78834 -0.889925 -0.068191</acceleration>
          <wrench>-0.309443 -0.410068 -1.07945 0 -0 0</wrench>
        </link>
        <link name='mirfl_caster_wheel_link'>
          <pose frame=''>3.60884 -2.26701 0.226567 0.001301 1.08731 1.64235</pose>
          <velocity>0.000203 -0.001628 -0.003462 -2.7845 -0.21216 0.029868</velocity>
          <acceleration>-0.41265 -1.28632 -3.47383 0.614824 1.08515 0.66102</acceleration>
          <wrench>-0.41265 -1.28632 -3.47383 0 -0 0</wrench>
        </link>
        <link name='mirfr_caster_rotation_link'>
          <pose frame=''>3.68732 -2.63347 0.163955 -0.000199 -0.419549 1.64304</pose>
          <velocity>-0.001663 -0.001398 -0.004775 0.003099 -0.019089 0.036572</velocity>
          <acceleration>-1.17417 -1.10745 -3.57923 0.811708 -1.4942 -1.87243</acceleration>
          <wrench>-0.363704 -0.343036 -1.10868 0 -0 0</wrench>
        </link>
        <link name='mirfr_caster_wheel_link'>
          <pose frame=''>3.6871 -2.63007 0.062546 -3.14123 1.04825 -1.49832</pose>
          <velocity>0.000133 -0.001004 -0.00477 0.072301 -0.013947 0.035819</velocity>
          <acceleration>-0.512306 -1.02662 -3.57411 0.710834 -0.566482 2.69503</acceleration>
          <wrench>-0.512306 -1.02662 -3.57411 0 -0 0</wrench>
        </link>
        <link name='mirleft_wheel_link'>
          <pose frame=''>3.26781 -2.27874 0.232255 0.568789 -0.722639 -0.18789</pose>
          <velocity>-0.000953 -0.0006 -0.004325 0.004144 -0.002538 -0.002129</velocity>
          <acceleration>-0.846646 -0.898687 -3.67669 0.30184 -0.627047 -0.456786</acceleration>
          <wrench>-0.846646 -0.898687 -3.67669 0 -0 0</wrench>
        </link>
        <link name='mirright_wheel_link'>
          <pose frame=''>3.35356 -2.67686 0.052401 1.57004 1.15488 1.78239</pose>
          <velocity>-0.002133 -0.000315 -0.0083 0.004693 -0.034326 -0.002244</velocity>
          <acceleration>-0.549008 -0.645187 -5.5729 -0.542739 0.0318 0.183969</acceleration>
          <wrench>-0.549008 -0.645187 -5.5729 0 -0 0</wrench>
        </link>
        <link name='right_inner_finger'>
          <pose frame=''>2.88904 -3.27018 0.734114 -1.44312 1.15089 1.64237</pose>
          <velocity>-0.026095 -0.050178 0.059779 -0.217768 0.599932 0.212159</velocity>
          <acceleration>10.5097 -79.0756 78.7831 -2.56859 0.04502 0.859714</acceleration>
          <wrench>0.109304 -0.822409 0.819368 0 -0 0</wrench>
        </link>
        <link name='right_inner_knuckle'>
          <pose frame=''>2.89722 -3.18194 0.773166 -1.74585 1.15088 1.64231</pose>
          <velocity>-0.003659 -0.040252 0.068059 -0.110338 -0.161862 0.344739</velocity>
          <acceleration>12.3336 -86.595 113.573 -1.76693 1.50333 -2.17449</acceleration>
          <wrench>0.334459 -2.34826 3.07983 0 -0 0</wrench>
        </link>
        <link name='right_outer_knuckle'>
          <pose frame=''>2.87841 -3.17947 0.774845 -1.5899 1.15091 1.64232</pose>
          <velocity>-0.004805 -0.043227 0.058096 -0.126135 0.585926 0.00575</velocity>
          <acceleration>0.410713 -90.92 94.2982 0.772501 -0.466327 -0.153372</acceleration>
          <wrench>0.012792 -2.83181 2.93703 0 -0 0</wrench>
        </link>
        <link name='shoulder_link'>
          <pose frame=''>3.65721 -2.80299 1.02733 -0.416628 0.052289 -2.95281</pose>
          <velocity>-0.003609 -0.004057 -0.005237 -0.046089 -0.008469 -0.056809</velocity>
          <acceleration>-0.91826 -0.212061 -3.32679 -1.02879 -1.49607 -0.728552</acceleration>
          <wrench>-3.39756 -0.784625 -12.3091 0 -0 0</wrench>
        </link>
        <link name='upper_arm_link'>
          <pose frame=''>3.68376 -2.92641 0.971579 -1.69942 1.15106 1.64198</pose>
          <velocity>0.001867 -5.4e-05 -0.007887 -0.063635 -0.009764 -0.02708</velocity>
          <acceleration>9.52213 14.4366 -17.2678 2.37079 -1.41 -0.886279</acceleration>
          <wrench>79.9192 121.166 -144.929 0 -0 0</wrench>
        </link>
        <link name='wrist_1_link'>
          <pose frame=''>2.85714 -2.96239 0.981855 -2.72457 -0.05212 0.188826</pose>
          <velocity>-0.003609 0.016464 -0.001949 -0.220762 -0.017053 -0.024146</velocity>
          <acceleration>-1.71924 4.82455 17.1552 -2.34026 -0.837082 0.355301</acceleration>
          <wrench>-2.09575 5.88113 20.9122 0 -0 0</wrench>
        </link>
        <link name='wrist_2_link'>
          <pose frame=''>2.88156 -3.07593 0.930487 -2.7245 -0.052177 0.188846</pose>
          <velocity>-0.005964 -0.000508 0.021888 -0.240718 -0.035911 -0.045052</velocity>
          <acceleration>14.6645 -46.9409 -5.37509 -3.02384 -0.953839 1.57311</acceleration>
          <wrench>17.876 -57.221 -6.55224 0 -0 0</wrench>
        </link>
        <link name='wrist_3_link'>
          <pose frame=''>2.87861 -3.03524 0.839128 -2.72451 -0.052261 0.188841</pose>
          <velocity>-0.004083 -0.026285 0.034777 -0.231804 -0.121294 -0.047034</velocity>
          <acceleration>13.9204 -75.6322 87.7656 -0.836392 -1.17295 -0.007522</acceleration>
          <wrench>6.46491 -35.1251 40.7601 0 -0 0</wrench>
        </link>
      </model>
      <light name='sun'>
        <pose frame=''>0 0 10 0 -0 0</pose>
      </light>
    </state>
    <gui fullscreen='0'>
      <camera name='user_camera'>
        <pose frame=''>0.589589 -2.74232 1.8414 0 0.423643 -0.131806</pose>
        <view_controller>orbit</view_controller>
        <projection_type>perspective</projection_type>
      </camera>
    </gui>
  </world>
</sdf>
